<?xml version="1.0" encoding="UTF-8"?>
<!-- Generated by org.testng.reporters.JUnitXMLReporter -->
<testsuite ignored="0" hostname="MSI" failures="3" tests="3" name="Default test" time="10.1" errors="0" timestamp="2023-11-26T14:33:12 IST">
  <testcase classname="DDT.DataDrivenSampleTest" name="Login" time="10.02">
    <failure type="org.testng.internal.thread.ThreadTimeoutException" message="Method DDT.DataDrivenSampleTest.Login() didn&amp;apos;t finish within the time-out 10000">
      <![CDATA[org.testng.internal.thread.ThreadTimeoutException: Method DDT.DataDrivenSampleTest.Login() didn't finish within the time-out 10000
at org.testng.internal.invokers.MethodInvocationHelper.invokeWithTimeoutWithNoExecutor(MethodInvocationHelper.java:360)
at org.testng.internal.invokers.MethodInvocationHelper.invokeWithTimeout(MethodInvocationHelper.java:301)
at org.testng.internal.invokers.TestInvoker.invokeMethod(TestInvoker.java:673)
at org.testng.internal.invokers.TestInvoker.invokeTestMethod(TestInvoker.java:227)
at org.testng.internal.invokers.TestMethodWithDataProviderMethodWorker.call(TestMethodWithDataProviderMethodWorker.java:80)
at org.testng.internal.invokers.TestMethodWithDataProviderMethodWorker.call(TestMethodWithDataProviderMethodWorker.java:17)
at java.base/java.util.concurrent.FutureTask.run(FutureTask.java:264)
at java.base/java.util.concurrent.Executors$RunnableAdapter.call(Executors.java:539)
at java.base/java.util.concurrent.FutureTask.run(FutureTask.java:264)
at java.base/java.util.concurrent.ThreadPoolExecutor.runWorker(ThreadPoolExecutor.java:1136)
at java.base/java.util.concurrent.ThreadPoolExecutor$Worker.run(ThreadPoolExecutor.java:635)
at java.base/java.lang.Thread.run(Thread.java:840)
]]>
    </failure>
  </testcase> <!-- Login -->
  <testcase classname="DDT.DataDrivenSampleTest" name="Login" time="10.02">
    <failure type="org.testng.internal.thread.ThreadTimeoutException" message="Method DDT.DataDrivenSampleTest.Login() didn&amp;apos;t finish within the time-out 10000">
      <![CDATA[org.testng.internal.thread.ThreadTimeoutException: Method DDT.DataDrivenSampleTest.Login() didn't finish within the time-out 10000
at org.testng.internal.invokers.MethodInvocationHelper.invokeWithTimeoutWithNoExecutor(MethodInvocationHelper.java:360)
at org.testng.internal.invokers.MethodInvocationHelper.invokeWithTimeout(MethodInvocationHelper.java:301)
at org.testng.internal.invokers.TestInvoker.invokeMethod(TestInvoker.java:673)
at org.testng.internal.invokers.TestInvoker.invokeTestMethod(TestInvoker.java:227)
at org.testng.internal.invokers.TestMethodWithDataProviderMethodWorker.call(TestMethodWithDataProviderMethodWorker.java:80)
at org.testng.internal.invokers.TestMethodWithDataProviderMethodWorker.call(TestMethodWithDataProviderMethodWorker.java:17)
at java.base/java.util.concurrent.FutureTask.run(FutureTask.java:264)
at java.base/java.util.concurrent.Executors$RunnableAdapter.call(Executors.java:539)
at java.base/java.util.concurrent.FutureTask.run(FutureTask.java:264)
at java.base/java.util.concurrent.ThreadPoolExecutor.runWorker(ThreadPoolExecutor.java:1136)
at java.base/java.util.concurrent.ThreadPoolExecutor$Worker.run(ThreadPoolExecutor.java:635)
at java.base/java.lang.Thread.run(Thread.java:840)
]]>
    </failure>
  </testcase> <!-- Login -->
  <testcase classname="DDT.DataDrivenSampleTest" name="Login" time="10.02">
    <failure type="org.testng.internal.thread.ThreadTimeoutException" message="Method DDT.DataDrivenSampleTest.Login() didn&amp;apos;t finish within the time-out 10000">
      <![CDATA[org.testng.internal.thread.ThreadTimeoutException: Method DDT.DataDrivenSampleTest.Login() didn't finish within the time-out 10000
at org.testng.internal.invokers.MethodInvocationHelper.invokeWithTimeoutWithNoExecutor(MethodInvocationHelper.java:360)
at org.testng.internal.invokers.MethodInvocationHelper.invokeWithTimeout(MethodInvocationHelper.java:301)
at org.testng.internal.invokers.TestInvoker.invokeMethod(TestInvoker.java:673)
at org.testng.internal.invokers.TestInvoker.invokeTestMethod(TestInvoker.java:227)
at org.testng.internal.invokers.TestMethodWithDataProviderMethodWorker.call(TestMethodWithDataProviderMethodWorker.java:80)
at org.testng.internal.invokers.TestMethodWithDataProviderMethodWorker.call(TestMethodWithDataProviderMethodWorker.java:17)
at java.base/java.util.concurrent.FutureTask.run(FutureTask.java:264)
at java.base/java.util.concurrent.Executors$RunnableAdapter.call(Executors.java:539)
at java.base/java.util.concurrent.FutureTask.run(FutureTask.java:264)
at java.base/java.util.concurrent.ThreadPoolExecutor.runWorker(ThreadPoolExecutor.java:1136)
at java.base/java.util.concurrent.ThreadPoolExecutor$Worker.run(ThreadPoolExecutor.java:635)
at java.base/java.lang.Thread.run(Thread.java:840)
]]>
    </failure>
  </testcase> <!-- Login -->
</testsuite> <!-- Default test -->
